<?xml version="1.0"?>
<robot xmlns:xacro="http://www.ros.org/wiki/xacro" name="skidbot">
    <xacro:include filename="$(find skidbot_description)/urdf/skidbot_gazebo.xacro"/> 
  <xacro:macro name="wheel_link" params="prefix">
    <link name="${prefix}_wheel_link">
      <visual>
        <origin xyz="0 0 0" rpy="1.570796327 0 0"/>
        <geometry>
          <cylinder length="0.07" radius="0.127"/>
        </geometry>
      </visual>
      <collision>
        <origin xyz="0 0 0" rpy="1.570796327 0 0"/>
        <geometry>
          <cylinder length="0.07" radius="0.127"/>
        </geometry>
      </collision>
          <inertial>
      <origin xyz="0 0 0" rpy="0 0 0"/>
      <mass value="0.1" />
      <inertia ixx="7.750e-3"
               ixy="0.0" iyy="4.546e-3"
               ixz="0.0" iyz="1.478e-5" izz="4.545e-3" />
    </inertial>
    </link>
    <gazebo reference="${prefix}_wheel_link">
     <material>Gazebo/Black</material>
    </gazebo>
  </xacro:macro>
  <!-- Use the macro to create a specific wheel link -->

   <link name="base_link">
    <visual>
      <origin xyz="0 0 0" rpy="0 0 0"/>
      <geometry>
        <box size="0.42 0.25 0.12"/>
      </geometry>
    </visual>
    <collision>
      <origin xyz="0 0 0" rpy="0 0 0"/>
      <geometry>
        <box size="0.42 0.25 0.12"/>
      </geometry>
    </collision>
    <inertial>
      <origin xyz="0 0 0" rpy="0 0 0" />
      <mass value="5" />
      <inertia ixx="1.340e-1"
               ixy="0.0" iyy="1.713e-1"
               ixz="0.0" iyz="1.815e-3" izz="5.917e-2" />
    </inertial>
  </link>
  
  <xacro:wheel_link prefix="left_front"/>
    <joint name="left_front_wheel_joint" type="continuous">
    <parent link="base_link"/>
    <child link="left_front_wheel_link"/>
    <origin xyz="0.142 0.18 0" rpy="0 0 0"/>
    <axis xyz="0 1 0"/>
  </joint>

  <xacro:wheel_link prefix="right_front"/>

  <joint name="right_front_wheel_joint" type="continuous">
    <parent link="base_link"/>
    <child link="right_front_wheel_link"/>
    <origin xyz="0.142 -0.18 0" rpy="0 0 0"/>
    <axis xyz="0 1 0"/>
  </joint>
    <xacro:wheel_link prefix="left_back"/>

  <joint name="left_back_wheel_joint" type="continuous">
    <parent link="base_link"/>
    <child link="left_back_wheel_link"/>
    <origin xyz="-0.142 0.18 0" rpy="0 0 0"/>
    <axis xyz="0 1 0"/>
  </joint>

  <xacro:wheel_link prefix="right_back"/>

  <joint name="right_back_wheel_joint" type="continuous">
    <parent link="base_link"/>
    <child link="right_back_wheel_link"/>
    <origin xyz="-0.142 -0.18 0" rpy="0 0 0"/>
    <axis xyz="0 1 0"/>
  </joint>
  <link name="middle_link">
    <visual>
      <geometry>
        <box size="0.42 0.25 0.02"/>
      </geometry>
    </visual>
    <collision>
      <geometry>
        <box size="0.42 0.25 0.02"/>
      </geometry>
    </collision>
    <inertial>
      <mass value="1" />
      <inertia ixx="1.340e-1"
               ixy="0.0" iyy="1.713e-1"
               ixz="0.0" iyz="1.815e-3" izz="5.917e-2" />
    </inertial>
  </link>
  <joint name="middle_joint" type="fixed">
    <parent link="base_link"/>
    <child link="middle_link"/>
    <origin xyz="0 0 0.15" rpy="0 0 0"/>
  </joint>
  <link name="bolt1_link">
    <visual>
      <geometry>
        <box size="0.02 0.02 0.1"/>
      </geometry>
    </visual>
    <collision>
      <geometry>
        <box size="0.02 0.02 0.1"/>
      </geometry>
    </collision>
    <inertial>
      <mass value="0.1" />
      <inertia ixx="1.340e-1"
               ixy="0.0" iyy="1.713e-1"
               ixz="0.0" iyz="1.815e-3" izz="5.917e-2" />
    </inertial>
  </link>
  <joint name="bolt1_joint" type="fixed">
    <parent link="base_link"/>
    <child link="bolt1_link"/>
    <origin xyz="0.2 0.115 0.1" rpy="0 0 0"/>
  </joint>
  <link name="bolt2_link">
    <visual>
      <geometry>
        <box size="0.02 0.02 0.1"/>
      </geometry>
    </visual>
    <collision>
      <geometry>
        <box size="0.02 0.02 0.1"/>
      </geometry>
    </collision>
    <inertial>
      <mass value="0.1" />
      <inertia ixx="1.340e-1"
               ixy="0.0" iyy="1.713e-1"
               ixz="0.0" iyz="1.815e-3" izz="5.917e-2" />
    </inertial>
  </link>
  <joint name="bolt2_joint" type="fixed">
    <parent link="base_link"/>
    <child link="bolt2_link"/>
    <origin xyz="-0.2 0.115 0.1" rpy="0 0 0"/>
  </joint>
  <link name="bolt3_link">
    <visual>
      <geometry>
        <box size="0.02 0.02 0.1"/>
      </geometry>
    </visual>
    <collision>
      <geometry>
        <box size="0.02 0.02 0.1"/>
      </geometry>
    </collision>
    <inertial>
      <mass value="0.1" />
      <inertia ixx="1.340e-1"
               ixy="0.0" iyy="1.713e-1"
               ixz="0.0" iyz="1.815e-3" izz="5.917e-2" />
    </inertial>
  </link>
  <joint name="bolt3_joint" type="fixed">
    <parent link="base_link"/>
    <child link="bolt3_link"/>
    <origin xyz="-0.2 -0.115 0.1" rpy="0 0 0"/>
  </joint>
  <link name="bolt4_link">
    <visual>
      <geometry>
        <box size="0.02 0.02 0.1"/>
      </geometry>
    </visual>
    <collision>
      <geometry>
        <box size="0.02 0.02 0.1"/>
      </geometry>
    </collision>
    <inertial>
      <mass value="0.1" />
      <inertia ixx="1.340e-1"
               ixy="0.0" iyy="1.713e-1"
               ixz="0.0" iyz="1.815e-3" izz="5.917e-2" />
    </inertial>
  </link>
  <joint name="bolt4_joint" type="fixed">
    <parent link="base_link"/>
    <child link="bolt4_link"/>
    <origin xyz="0.2 -0.115 0.1" rpy="0 0 0"/>
  </joint>
  <link name="side1_link">
    <visual>
      <geometry>
        <box size="0.42 0.02 0.07"/>
      </geometry>
    </visual>
    <collision>
      <geometry>
        <box size="0.42 0.02 0.1"/>
      </geometry>
    </collision>
    <inertial>
      <mass value="0.1" />
      <inertia ixx="1.340e-1"
               ixy="0.0" iyy="1.713e-1"
               ixz="0.0" iyz="1.815e-3" izz="5.917e-2" />
    </inertial>
  </link>
  <joint name="side1_joint" type="fixed">
    <parent link="base_link"/>
    <child link="side1_link"/>
    <origin xyz="0 -0.115 0.19" rpy="0 0 0"/>
  </joint>
  <link name="side2_link">
    <visual>
      <geometry>
        <box size="0.02 0.25 0.07"/>
      </geometry>
    </visual>
    <collision>
      <geometry>
        <box size="0.02 0.25 0.07"/>
      </geometry>
    </collision>
    <inertial>
      <mass value="0.1" />
      <inertia ixx="1.340e-1"
               ixy="0.0" iyy="1.713e-1"
               ixz="0.0" iyz="1.815e-3" izz="5.917e-2" />
    </inertial>
  </link>
  <joint name="side2_joint" type="fixed">
    <parent link="base_link"/>
    <child link="side2_link"/>
    <origin xyz="0.2 0 0.19" rpy="0 0 0"/>
  </joint>
  <link name="side3_link">
    <visual>
      <geometry>
        <box size="0.42 0.02 0.07"/>
      </geometry>
    </visual>
    <collision>
      <geometry>
        <box size="0.42 0.02 0.07"/>
      </geometry>
    </collision>
    <inertial>
      <mass value="0.1" />
      <inertia ixx="1.340e-1"
               ixy="0.0" iyy="1.713e-1"
               ixz="0.0" iyz="1.815e-3" izz="5.917e-2" />
    </inertial>
  </link>
  <joint name="side3_joint" type="fixed">
    <parent link="base_link"/>
    <child link="side3_link"/>
    <origin xyz="0 0.115 0.19" rpy="0 0 0"/>
  </joint>
  <link name="side4_link">
    <visual>
      <geometry>
        <box size="0.02 0.25 0.07"/>
      </geometry>
    </visual>
    <collision>
      <geometry>
        <box size="0.02 0.25 0.07"/>
      </geometry>
    </collision>
    <inertial>
      <mass value="0.1" />
      <inertia ixx="1.340e-1"
               ixy="0.0" iyy="1.713e-1"
               ixz="0.0" iyz="1.815e-3" izz="5.917e-2" />
    </inertial>
  </link>
  <joint name="side4_joint" type="fixed">
    <parent link="base_link"/>
    <child link="side4_link"/>
    <origin xyz="-0.2 0 0.19" rpy="0 0 0"/>
  </joint>      
</robot>